Workbook

Sheet Dashboard
B2: IRISH HOUSING MARKET — PRICE & AFFORDABILITY DASHBOARD
B3: CSO Residential Property Price Index (HPA06) — National, Dublin & Regional, 2005-2025
B5: NATIONAL INDEX 2025 (Jan05=100) | D5: FASTEST-GROWING REGION (2025 YoY) | F5: DUBLIN 2025 YoY GROWTH | H5: AFFORDABILITY GAP (pp) | J5: PEAK-TROUGH SWING (Nat'l, pts)
B6: =Dublin_vs_Rest!D22 -> 157.9 | D6: =ROUND(MAX(Regional_Summary_2025!C2:C15),1) -> 11.8 | F6: =ROUND(INDEX(Regional_Summary_2025!C2:C15,MATCH("Dublin",Regional_Summary_2025!A2:A15,0)),1) -> 6.1 | H6: =Affordability!C14 -> 6.4 | J6: =100.9 -> 100.9

Sheet Data
A1: Year | B1: Region | C1: PropertyType | D1: PriceIndex | E1: YoY_Growth_Pct
A2: 2010 | B2: Border (ex-Louth) | C2: houses | D2: 89.3
A3: 2011 | B3: Border (ex-Louth) | C3: houses | D3: 74.8 | E3: -16.24
A4: 2012 | B4: Border (ex-Louth) | C4: houses | D4: 59.3 | E4: -20.72
A5: 2013 | B5: Border (ex-Louth) | C5: houses | D5: 50.3 | E5: -15.18
A6: 2014 | B6: Border (ex-Louth) | C6: houses | D6: 50.6 | E6: 0.6
A7: 2015 | B7: Border (ex-Louth) | C7: houses | D7: 56.2 | E7: 11.07
A8: 2016 | B8: Border (ex-Louth) | C8: houses | D8: 61.3 | E8: 9.07
A9: 2017 | B9: Border (ex-Louth) | C9: houses | D9: 67.9 | E9: 10.77
A10: 2018 | B10: Border (ex-Louth) | C10: houses | D10: 72.7 | E10: 7.07
A11: 2019 | B11: Border (ex-Louth) | C11: houses | D11: 80 | E11: 10.04
A12: 2020 | B12: Border (ex-Louth) | C12: houses | D12: 80.3 | E12: 0.37
A13: 2021 | B13: Border (ex-Louth) | C13: houses | D13: 91.3 | E13: 13.7
A14: 2022 | B14: Border (ex-Louth) | C14: houses | D14: 107.7 | E14: 17.96
... A17: 2025 | B17: Border (ex-Louth) | C17: houses | D17: 134.7 | E17: 8.98
A18: 2005 | B18: Dublin | C18: all residential properties | D18: 106.9
A19: 2006 | B19: Dublin | C19: all residential properties | D19: 126.2 | E19: 18.05
A20: 2007 | B20: Dublin | C20: all residential properties | D20: 133.2 | E20: 5.55
A21: 2008 | B21: Dublin | C21: all residential properties | D21: 121 | E21: -9.16
A22: 2009 | B22: Dublin | C22: all residential properties | D22: 91.4 | E22: -24.46
A23: 2010 | B23: Dublin | C23: all residential properties | D23: 75.9 | E23: -16.96
A24: 2011 | B24: Dublin | C24: all residential properties | D24: 63.7 | E24: -16.07
A25: 2012 | B25: Dublin | C25: all residential properties | D25: 56.3 | E25: -11.62
A26: 2013 | B26: Dublin | C26: all residential properties | D26: 61.8 | E26: 9.77
A27: 2014 | B27: Dublin | C27: all residential properties | D27: 76.7 | E27: 24.11
A28: 2015 | B28: Dublin | C28: all residential properties | D28: 84.4 | E28: 10.04
A29: 2016 | B29: Dublin | C29: all residential properties | D29: 88.7 | E29: 5.09
A30: 2017 | B30: Dublin | C30: all residential properties | D30: 97.1 | E30: 9.47
... A38: 2025 | B38: Dublin | C38: all residential properties | D38: 143.9 | E38: 6.12
A39: 2005 | B39: Dublin | C39: apartments | D39: 105.3
A40: 2006 | B40: Dublin | C40: apartments | D40: 118.9 | E40: 12.92
A41: 2007 | B41: Dublin | C41: apartments | D41: 124.2 | E41: 4.46
A42: 2008 | B42: Dublin | C42: apartments | D42: 111.8 | E42: -9.98
A43: 2009 | B43: Dublin | C43: apartments | D43: 81.3 | E43: -27.28
A44: 2010 | B44: Dublin | C44: apartments | D44: 67 | E44: -17.59
A45: 2011 | B45: Dublin | C45: apartments | D45: 56.9 | E45: -15.07
A46: 2012 | B46: Dublin | C46: apartments | D46: 47.1 | E46: -17.22
A47: 2013 | B47: Dublin | C47: apartments | D47: 49.4 | E47: 4.88
A48: 2014 | B48: Dublin | C48: apartments | D48: 62.2 | E48: 25.91
A49: 2015 | B49: Dublin | C49: apartments | D49: 69.5 | E49: 11.74
...

Sheet Regional_Summary_2025
A1: Region | B1: 2025 Index (houses) | C1: 2025 YoY Growth % | D1: 2020-2025 Growth %
A2: Border (ex-Louth) | B2: =ROUND(SUMIFS(Data!$D$2:$D$366,Data!$B$2:$B$366,A2,Data!$C$2:$C$366,"houses",Data!$A$2:$A$366,2025),1) -> 134.7 | C2: =ROUND(SUMIFS(Data!$E$2:$E$366,Data!$B$2:$B$366,A2,Data!$C$2:$C$366,"houses",Data!$A$2:$A$366,2025),2) -> 8.98 | D2: =IFERROR(ROUND((B2-SUMIFS(Data!$D$2:$D$366,Data!$B$2:$B$366,A2,Data!$C$2:$C$366,"houses",Data!$A$2:$A$366,2020))/SUMIFS(Data!$D$2:$D$366,Data!$B$2:$B$366,A2,Data!$C$2:$C$366,"houses",Data!$A$2:$A$366,2020)*100,1),"n/a") -> 67.7
A3: Dublin | B3: =ROUND(SUMIFS(Data!$D$2:$D$366,Data!$B$2:$B$366,A3,Data!$C$2:$C$366,"houses",Data!$A$2:$A$366,2025),1) -> 152.4 | C3: =ROUND(SUMIFS(Data!$E$2:$E$366,Data!$B$2:$B$366,A3,Data!$C$2:$C$366,"houses",Data!$A$2:$A$366,2025),2) -> 6.05 | D3: =IFERROR(ROUND((B3-SUMIFS(Data!$D$2:$D$366,Data!$B$2:$B$366,A3,Data!$C$2:$C$366,"houses",Data!$A$2:$A$366,2020))/SUMIFS(Data!$D$2:$D$366,Data!$B$2:$B$366,A3,Data!$C$2:$C$366,"houses",Data!$A$2:$A$366,2020)*100,1),"n/a") -> 38.4
A4: Dublin City | B4: =ROUND(SUMIFS(Data!$D$2:$D$366,Data!$B$2:$B$366,A4,Data!$C$2:$C$366,"houses",Data!$A$2:$A$366,2025),1) -> 153.5 | C4: =ROUND(SUMIFS(Data!$E$2:$E$366,Data!$B$2:$B$366,A4,Data!$C$2:$C$366,"houses",Data!$A$2:$A$366,2025),2) -> 6.75 | D4: =IFERROR(ROUND((B4-SUMIFS(Data!$D$2:$D$366,Data!$B$2:$B$366,A4,Data!$C$2:$C$366,"houses",Data!$A$2:$A$366,2020))/SUMIFS(Data!$D$2:$D$366,Data!$B$2:$B$366,A4,Data!$C$2:$C$366,"houses",Data!$A$2:$A$366,2020)*100,1),"n/a") -> 38.9
A5: Dun Laoghaire-Rathdown | B5: =ROUND(SUMIFS(Data!$D$2:$D$366,Data!$B$2:$B$366,A5,Data!$C$2:$C$366,"houses",Data!$A$2:$A$366,2025),1) -> 143.1 | C5: =ROUND(SUMIFS(Data!$E$2:$E$366,Data!$B$2:$B$366,A5,Data!$C$2:$C$366,"houses",Data!$A$2:$A$366,2025),2) -> 5.07 | D5: =IFERROR(ROUND((B5-SUMIFS(Data!$D$2:$D$366,Data!$B$2:$B$366,A5,Data!$C$2:$C$366,"houses",Data!$A$2:$A$366,2020))/SUMIFS(Data!$D$2:$D$366,Data!$B$2:$B$366,A5,Data!$C$2:$C$366,"houses",Data!$A$2:$A$366,2020)*100,1),"n/a") -> 33.4
A6: Fingal | B6: =ROUND(SUMIFS(Data!$D$2:$D$366,Data!$B$2:$B$366,A6,Data!$C$2:$C$366,"houses",Data!$A$2:$A$366,2025),1) -> 149.3 | C6: =ROUND(SUMIFS(Data!$E$2:$E$366,Data!$B$2:$B$366,A6,Data!$C$2:$C$366,"houses",Data!$A$2:$A$366,2025),2) -> 6.72 | D6: =IFERROR(ROUND((B6-SUMIFS(Data!$D$2:$D$366,Data!$B$2:$B$366,A6,Data!$C$2:$C$366,"houses",Data!$A$2:$A$366,2020))/SUMIFS(Data!$D$2:$D$366,Data!$B$2:$B$366,A6,Data!$C$2:$C$366,"houses",Data!$A$2:$A$366,2020)*100,1),"n/a") -> 39.8
A7: Mid-East (incl. Louth) | B7: =ROUND(SUMIFS(Data!$D$2:$D$366,Data!$B$2:$B$366,A7,Data!$C$2:$C$366,"houses",Data!$A$2:$A$366,2025),1) -> 168.2 | C7: =ROUND(SUMIFS(Data!$E$2:$E$366,Data!$B$2:$B$366,A7,Data!$C$2:$C$366,"houses",Data!$A$2:$A$366,2025),2) -> 7.75 | D7: =IFERROR(ROUND((B7-SUMIFS(Data!$D$2:$D$366,Data!$B$2:$B$366,A7,Data!$C$2:$C$366,"houses",Data!$A$2:$A$366,2020))/SUMIFS(Data!$D$2:$D$366,Data!$B$2:$B$366,A7,Data!$C$2:$C$366,"houses",Data!$A$2:$A$366,2020)*100,1),"n/a") -> 48.5
A8: Mid-West (incl. S. Tipp) | B8: =ROUND(SUMIFS(Data!$D$2:$D$366,Data!$B$2:$B$366,A8,Data!$C$2:$C$366,"houses",Data!$A$2:$A$366,2025),1) -> 149.9 | C8: =ROUND(SUMIFS(Data!$E$2:$E$366,Data!$B$2:$B$366,A8,Data!$C$2:$C$366,"houses",Data!$A$2:$A$366,2025),2) -> 10.14 | D8: =IFERROR(ROUND((B8-SUMIFS(Data!$D$2:$D$366,Data!$B$2:$B$366,A8,Data!$C$2:$C$366,"houses",Data!$A$2:$A$366,2020))/SUMIFS(Data!$D$2:$D$366,Data!$B$2:$B$366,A8,Data!$C$2:$C$366,"houses",Data!$A$2:$A$366,2020)*100,1),"n/a") -> 56
A9: Midland | B9: =ROUND(SUMIFS(Data!$D$2:$D$366,Data!$B$2:$B$366,A9,Data!$C$2:$C$366,"houses",Data!$A$2:$A$366,2025),1) -> 156.8 | C9: =ROUND(SUMIFS(Data!$E$2:$E$366,Data!$B$2:$B$366,A9,Data!$C$2:$C$366,"houses",Data!$A$2:$A$366,2025),2) -> 11.76 | D9: =IFERROR(ROUND((B9-SUMIFS(Data!$D$2:$D$366,Data!$B$2:$B$366,A9,Data!$C$2:$C$366,"houses",Data!$A$2:$A$366,2020))/SUMIFS(Data!$D$2:$D$366,Data!$B$2:$B$366,A9,Data!$C$2:$C$366,"houses",Data!$A$2:$A$366,2020)*100,1),"n/a") -> 64.4
A10: National | B10: =ROUND(SUMIFS(Data!$D$2:$D$366,Data!$B$2:$B$366,A10,Data!$C$2:$C$366,"houses",Data!$A$2:$A$366,2025),1) -> 164.3 | C10: =ROUND(SUMIFS(Data!$E$2:$E$366,Data!$B$2:$B$366,A10,Data!$C$2:$C$366,"houses",Data!$A$2:$A$366,2025),2) -> 7.67 | D10: =IFERROR(ROUND((B10-SUMIFS(Data!$D$2:$D$366,Data!$B$2:$B$366,A10,Data!$C$2:$C$366,"houses",Data!$A$2:$A$366,2020))/SUMIFS(Data!$D$2:$D$366,Data!$B$2:$B$366,A10,Data!$C$2:$C$366,"houses",Data!$A$2:$A$366,2020)*100,1),"n/a") -> 47.4
A11: National ex-Dublin | B11: =ROUND(SUMIFS(Data!$D$2:$D$366,Data!$B$2:$B$366,A11,Data!$C$2:$C$366,"houses",Data!$A$2:$A$366,2025),1) -> 160.8 | C11: =ROUND(SUMIFS(Data!$E$2:$E$366,Data!$B$2:$B$366,A11,Data!$C$2:$C$366,"houses",Data!$A$2:$A$366,2025),2) -> 8.72 | D11: =IFERROR(ROUND((B11-SUMIFS(Data!$D$2:$D$366,Data!$B$2:$B$366,A11,Data!$C$2:$C$366,"houses",Data!$A$2:$A$366,2020))/SUMIFS(Data!$D$2:$D$366,Data!$B$2:$B$366,A11,Data!$C$2:$C$366,"houses",Data!$A$2:$A$366,2020)*100,1),"n/a") -> 53.7
A12: South Dublin | B12: =ROUND(SUMIFS(Data!$D$2:$D$366,Data!$B$2:$B$366,A12,Data!$C$2:$C$366,"houses",Data!$A$2:$A$366,2025),1) -> 159.9 | C12: =ROUND(SUMIFS(Data!$E$2:$E$366,Data!$B$2:$B$366,A12,Data!$C$2:$C$366,"houses",Data!$A$2:$A$366,2025),2) -> 5.82 | D12: =IFERROR(ROUND((B12-SUMIFS(Data!$D$2:$D$366,Data!$B$2:$B$366,A12,Data!$C$2:$C$366,"houses",Data!$A$2:$A$366,2020))/SUMIFS(Data!$D$2:$D$366,Data!$B$2:$B$366,A12,Data!$C$2:$C$366,"houses",Data!$A$2:$A$366,2020)*100,1),"n/a") -> 44.8
A13: South-East (ex-S. Tipp) | B13: =ROUND(SUMIFS(Data!$D$2:$D$366,Data!$B$2:$B$366,A13,Data!$C$2:$C$366,"houses",Data!$A$2:$A$366,2025),1) -> 156 | C13: =ROUND(SUMIFS(Data!$E$2:$E$366,Data!$B$2:$B$366,A13,Data!$C$2:$C$366,"houses",Data!$A$2:$A$366,2025),2) -> 7.66 | D13: =IFERROR(ROUND((B13-SUMIFS(Data!$D$2:$D$366,Data!$B$2:$B$366,A13,Data!$C$2:$C$366,"houses",Data!$A$2:$A$366,2020))/SUMIFS(Data!$D$2:$D$366,Data!$B$2:$B$366,A13,Data!$C$2:$C$366,"houses",Data!$A$2:$A$366,2020)*100,1),"n/a") -> 56
... A15: West | B15: =ROUND(SUMIFS(Data!$D$2:$D$366,Data!$B$2:$B$366,A15,Data!$C$2:$C$366,"houses",Data!$A$2:$A$366,2025),1) -> 163.2 | C15: =ROUND(SUMIFS(Data!$E$2:$E$366,Data!$B$2:$B$366,A15,Data!$C$2:$C$366,"houses",Data!$A$2:$A$366,2025),2) -> 8.44 | D15: =IFERROR(ROUND((B15-SUMIFS(Data!$D$2:$D$366,Data!$B$2:$B$366,A15,Data!$C$2:$C$366,"houses",Data!$A$2:$A$366,2020))/SUMIFS(Data!$D$2:$D$366,Data!$B$2:$B$366,A15,Data!$C$2:$C$366,"houses",Data!$A$2:$A$366,2020)*100,1),"n/a") -> 56.6

Sheet Dublin_vs_Rest
A1: Year | B1: Dublin_Index | C1: RestOfCountry_Index | D1: National_Index
A2: 2005 | B2: =ROUND(SUMIFS(Data!$D$2:$D$366,Data!$A$2:$A$366,A2,Data!$B$2:$B$366,"Dublin",Data!$C$2:$C$366,"all residential properties"),1) -> 106.9 | C2: =ROUND(SUMIFS(Data!$D$2:$D$366,Data!$A$2:$A$366,A2,Data!$B$2:$B$366,"National ex-Dublin",Data!$C$2:$C$366,"all residential properties"),1) -> 104.7 | D2: =ROUND(SUMIFS(Data!$D$2:$D$366,Data!$A$2:$A$366,A2,Data!$B$2:$B$366,"National",Data!$C$2:$C$366,"all residential properties"),1) -> 105.5
A3: 2006 | B3: =ROUND(SUMIFS(Data!$D$2:$D$366,Data!$A$2:$A$366,A3,Data!$B$2:$B$366,"Dublin",Data!$C$2:$C$366,"all residential properties"),1) -> 126.2 | C3: =ROUND(SUMIFS(Data!$D$2:$D$366,Data!$A$2:$A$366,A3,Data!$B$2:$B$366,"National ex-Dublin",Data!$C$2:$C$366,"all residential properties"),1) -> 118.4 | D3: =ROUND(SUMIFS(Data!$D$2:$D$366,Data!$A$2:$A$366,A3,Data!$B$2:$B$366,"National",Data!$C$2:$C$366,"all residential properties"),1) -> 121.2
A4: 2007 | B4: =ROUND(SUMIFS(Data!$D$2:$D$366,Data!$A$2:$A$366,A4,Data!$B$2:$B$366,"Dublin",Data!$C$2:$C$366,"all residential properties"),1) -> 133.2 | C4: =ROUND(SUMIFS(Data!$D$2:$D$366,Data!$A$2:$A$366,A4,Data!$B$2:$B$366,"National ex-Dublin",Data!$C$2:$C$366,"all residential properties"),1) -> 128.5 | D4: =ROUND(SUMIFS(Data!$D$2:$D$366,Data!$A$2:$A$366,A4,Data!$B$2:$B$366,"National",Data!$C$2:$C$366,"all residential properties"),1) -> 130.3
A5: 2008 | B5: =ROUND(SUMIFS(Data!$D$2:$D$366,Data!$A$2:$A$366,A5,Data!$B$2:$B$366,"Dublin",Data!$C$2:$C$366,"all residential properties"),1) -> 121 | C5: =ROUND(SUMIFS(Data!$D$2:$D$366,Data!$A$2:$A$366,A5,Data!$B$2:$B$366,"National ex-Dublin",Data!$C$2:$C$366,"all residential properties"),1) -> 121.1 | D5: =ROUND(SUMIFS(Data!$D$2:$D$366,Data!$A$2:$A$366,A5,Data!$B$2:$B$366,"National",Data!$C$2:$C$366,"all residential properties"),1) -> 121.2
A6: 2009 | B6: =ROUND(SUMIFS(Data!$D$2:$D$366,Data!$A$2:$A$366,A6,Data!$B$2:$B$366,"Dublin",Data!$C$2:$C$366,"all residential properties"),1) -> 91.4 | C6: =ROUND(SUMIFS(Data!$D$2:$D$366,Data!$A$2:$A$366,A6,Data!$B$2:$B$366,"National ex-Dublin",Data!$C$2:$C$366,"all residential properties"),1) -> 101 | D6: =ROUND(SUMIFS(Data!$D$2:$D$366,Data!$A$2:$A$366,A6,Data!$B$2:$B$366,"National",Data!$C$2:$C$366,"all residential properties"),1) -> 98
A7: 2010 | B7: =ROUND(SUMIFS(Data!$D$2:$D$366,Data!$A$2:$A$366,A7,Data!$B$2:$B$366,"Dublin",Data!$C$2:$C$366,"all residential properties"),1) -> 75.9 | C7: =ROUND(SUMIFS(Data!$D$2:$D$366,Data!$A$2:$A$366,A7,Data!$B$2:$B$366,"National ex-Dublin",Data!$C$2:$C$366,"all residential properties"),1) -> 89 | D7: =ROUND(SUMIFS(Data!$D$2:$D$366,Data!$A$2:$A$366,A7,Data!$B$2:$B$366,"National",Data!$C$2:$C$366,"all residential properties"),1) -> 84.8
A8: 2011 | B8: =ROUND(SUMIFS(Data!$D$2:$D$366,Data!$A$2:$A$366,A8,Data!$B$2:$B$366,"Dublin",Data!$C$2:$C$366,"all residential properties"),1) -> 63.7 | C8: =ROUND(SUMIFS(Data!$D$2:$D$366,Data!$A$2:$A$366,A8,Data!$B$2:$B$366,"National ex-Dublin",Data!$C$2:$C$366,"all residential properties"),1) -> 73.1 | D8: =ROUND(SUMIFS(Data!$D$2:$D$366,Data!$A$2:$A$366,A8,Data!$B$2:$B$366,"National",Data!$C$2:$C$366,"all residential properties"),1) -> 70.3
A9: 2012 | B9: =ROUND(SUMIFS(Data!$D$2:$D$366,Data!$A$2:$A$366,A9,Data!$B$2:$B$366,"Dublin",Data!$C$2:$C$366,"all residential properties"),1) -> 56.3 | C9: =ROUND(SUMIFS(Data!$D$2:$D$366,Data!$A$2:$A$366,A9,Data!$B$2:$B$366,"National ex-Dublin",Data!$C$2:$C$366,"all residential properties"),1) -> 62 | D9: =ROUND(SUMIFS(Data!$D$2:$D$366,Data!$A$2:$A$366,A9,Data!$B$2:$B$366,"National",Data!$C$2:$C$366,"all residential properties"),1) -> 60.9
A10: 2013 | B10: =ROUND(SUMIFS(Data!$D$2:$D$366,Data!$A$2:$A$366,A10,Data!$B$2:$B$366,"Dublin",Data!$C$2:$C$366,"all residential properties"),1) -> 61.8 | C10: =ROUND(SUMIFS(Data!$D$2:$D$366,Data!$A$2:$A$366,A10,Data!$B$2:$B$366,"National ex-Dublin",Data!$C$2:$C$366,"all residential properties"),1) -> 57.7 | D10: =ROUND(SUMIFS(Data!$D$2:$D$366,Data!$A$2:$A$366,A10,Data!$B$2:$B$366,"National",Data!$C$2:$C$366,"all residential properties"),1) -> 61.6
A11: 2014 | B11: =ROUND(SUMIFS(Data!$D$2:$D$366,Data!$A$2:$A$366,A11,Data!$B$2:$B$366,"Dublin",Data!$C$2:$C$366,"all residential properties"),1) -> 76.7 | C11: =ROUND(SUMIFS(Data!$D$2:$D$366,Data!$A$2:$A$366,A11,Data!$B$2:$B$366,"National ex-Dublin",Data!$C$2:$C$366,"all residential properties"),1) -> 62.2 | D11: =ROUND(SUMIFS(Data!$D$2:$D$366,Data!$A$2:$A$366,A11,Data!$B$2:$B$366,"National",Data!$C$2:$C$366,"all residential properties"),1) -> 71.8
A12: 2015 | B12: =ROUND(SUMIFS(Data!$D$2:$D$366,Data!$A$2:$A$366,A12,Data!$B$2:$B$366,"Dublin",Data!$C$2:$C$366,"all residential properties"),1) -> 84.4 | C12: =ROUND(SUMIFS(Data!$D$2:$D$366,Data!$A$2:$A$366,A12,Data!$B$2:$B$366,"National ex-Dublin",Data!$C$2:$C$366,"all residential properties"),1) -> 70.4 | D12: =ROUND(SUMIFS(Data!$D$2:$D$366,Data!$A$2:$A$366,A12,Data!$B$2:$B$366,"National",Data!$C$2:$C$366,"all residential properties"),1) -> 80.1
A13: 2016 | B13: =ROUND(SUMIFS(Data!$D$2:$D$366,Data!$A$2:$A$366,A13,Data!$B$2:$B$366,"Dublin",Data!$C$2:$C$366,"all residential properties"),1) -> 88.7 | C13: =ROUND(SUMIFS(Data!$D$2:$D$366,Data!$A$2:$A$366,A13,Data!$B$2:$B$366,"National ex-Dublin",Data!$C$2:$C$366,"all residential properties"),1) -> 77.4 | D13: =ROUND(SUMIFS(Data!$D$2:$D$366,Data!$A$2:$A$366,A13,Data!$B$2:$B$366,"National",Data!$C$2:$C$366,"all residential properties"),1) -> 86
... A22: 2025 | B22: =ROUND(SUMIFS(Data!$D$2:$D$366,Data!$A$2:$A$366,A22,Data!$B$2:$B$366,"Dublin",Data!$C$2:$C$366,"all residential properties"),1) -> 143.9 | C22: =ROUND(SUMIFS(Data!$D$2:$D$366,Data!$A$2:$A$366,A22,Data!$B$2:$B$366,"National ex-Dublin",Data!$C$2:$C$366,"all residential properties"),1) -> 158.5 | D22: =ROUND(SUMIFS(Data!$D$2:$D$366,Data!$A$2:$A$366,A22,Data!$B$2:$B$366,"National",Data!$C$2:$C$366,"all residential properties"),1) -> 157.9

Sheet Affordability
A1: AFFORDABILITY: House Price Growth vs. Average Weekly Earnings Growth
A3: Period | B3: Metric | C3: Value
A4: Q1 2024 | B4: Avg. weekly earnings (CSO, all sectors) | C4: 972.2
A5: Q1 2025 | B5: Avg. weekly earnings (CSO, all sectors) | C5: 1026.2
A6: Q1 2026 | B6: Avg. weekly earnings (CSO, all sectors) | C6: 1075.58
A7: 2023 | B7: National house price index (houses) | C7: 140.4
A8: 2024 | B8: National house price index (houses) | C8: 152.6
A9: 2025 | B9: National house price index (houses) | C9: 164.3
A11: Earnings growth, Q1 2024 -> Q1 2026: | C11: =ROUND((C6-C4)/C4*100,1) -> 10.6
A12: House price growth, 2023 -> 2025: | C12: =ROUND((C9-C7)/C7*100,1) -> 17
A14: Affordability gap (price growth minus earnings growth, pp): | C14: =ROUND(C12-C11,1) -> 6.4
A16: Note: CSO earnings series (Earnings & Labour Costs release) is only readily available for recent quarters in this project; house price index goes back to 2005. Affordability comparison uses the most recent comparable 2-year window rather than the full 20-year span.
